<?xml version="1.0" ?>
<!-- =================================================================================== -->
<!-- |    This document was autogenerated by xacro from model_impactor.urdf.xacro      | -->
<!-- |    EDITING THIS FILE BY HAND IS NOT RECOMMENDED                                 | -->
<!-- =================================================================================== -->
<robot name="bros300">
 <properties mass="1.21" arm="0.15" kf="4.5e-8" km="5.4e-10" thrust2weight="6.944"  max_speed_kmh="200" gnd_eff_coeff="11.36859" prop_radius="0.089" drag_coeff_xy="9.1785e-7" drag_coeff_z="10.311e-7" dw_coeff_1="2267.18" dw_coeff_2=".16" dw_coeff_3="-.11" />

  <material name="blue">
    <color rgba="0.2 0.2 0.2 1"/>
  </material>
  <material name="gray">
    <color rgba="0.25 0.25 0.25 1"/>
  </material>
  <material name="dark_gray">
    <color rgba="0.2 0.2 0.2 1"/>
  </material>
  <material name="pink">
    <color rgba="1.0 0.2 0.8 1"/>
  </material>
  <material name="purple">
    <color rgba="0.8 0.2 0.8 1"/>
  </material>
  <material name="red">
    <color rgba="1.0 0.2 0.2 1"/>
  </material>
  <material name="orange">
    <color rgba="1.0 0.5 0.0 1"/>
  </material>
  <material name="green">
    <color rgba="0.2 0.8 0.2 1"/>
  </material>

  <link name="base_link">
    <inertial>
      <origin rpy="0 0 0" xyz="0 0 0"/>
      <mass value="1.21"/>
      <inertia ixx=".007" ixy="0.0" ixz="0.0" iyy=".007" iyz="0.0" izz=".01"/>
    </inertial>
    <visual>
      <origin rpy="0 0 55" xyz="0 0 0.075"/>
      <geometry>
        <mesh filename="./mesh/a300/frame.stl" scale="0.001 0.001 0.001"/>
      </geometry> 
      <material name="frame">
        <color rgba="0.2 0.2 0.2 1"/>
      </material> 
    </visual>

<!-- Motors (Visual Only) -->
    <visual>
      <origin rpy="0 0 55" xyz="0.106 -0.106 0.075"/>
      <geometry>
        <mesh filename="./mesh/a300/motor.stl" scale="0.001 0.001 0.001"/>
      </geometry> 
      <material name="motor">
        <color rgba="0 .0 .0 1"/>
      </material> 
    </visual>
    <visual>
      <origin rpy="0 0 55" xyz="-0.106 0.106 0.075"/>
      <geometry>
        <mesh filename="./mesh/a300/motor.stl" scale="0.001 0.001 0.001"/>
      </geometry> 
      <material name="motor">
        <color rgba="0 .0 .0 1"/>
      </material> 
    </visual>
    <visual>
      <origin rpy="0 0 55" xyz="0.106 0.106 0.075"/>
      <geometry>
        <mesh filename="./mesh/a300/motor.stl" scale="0.001 0.001 0.001"/>
      </geometry> 
      <material name="motor">
        <color rgba="0 .0 .0 1"/>
      </material> 
    </visual>
    <visual>
      <origin rpy="0 0 55" xyz="-0.106 -0.106 0.075"/>
      <geometry>
        <mesh filename="./mesh/a300/motor.stl" scale="0.001 0.001 0.001"/>
      </geometry> 
      <material name="motor">
        <color rgba="0 .0 .0 1"/>
      </material> 
    </visual>

<!-- Legs (Visual Only) -->
    <visual>
      <origin rpy="0 0 0" xyz="0.106 -0.106 -0.03"/>
      <geometry>
        <cylinder radius="0.015" length="0.06"/>
      </geometry>
      <material name="red"><color rgba="1 0 0 1"/></material>
    </visual>
    <visual>
      <origin rpy="0 0 0" xyz="-0.106 0.106 -0.03"/>
      <geometry>
        <cylinder radius="0.015" length="0.06"/>
      </geometry>
      <material name="black"><color rgba="0 0 0 1"/></material>
    </visual>
    <visual>
      <origin rpy="0 0 0" xyz="0.106 0.106 -0.03"/>
      <geometry>
        <cylinder radius="0.015" length="0.06"/>
      </geometry>
      <material name="red"><color rgba="1 0 0 1"/></material>
    </visual>
    <visual>
      <origin rpy="0 0 0" xyz="-0.106 -0.106 -0.03"/>
      <geometry>
        <cylinder radius="0.015" length="0.06"/>
      </geometry>
      <material name="black"><color rgba="0 0 0 1"/></material>
    </visual>

    <collision>
      <origin rpy="0 0 0" xyz="0 0 0"/>
      <geometry>
        <box size=".16 .16 .05"/>
      </geometry>
    </collision>
  </link>

  <!-- <joint name="fixed_to_world" type="fixed">
    <parent link="world"/>
    <child link="base_link"/>
    <origin rpy="0 0 0" xyz="0 0 0"/>
  </joint> -->

<!-- Propellers -->
  <link name="prop0_link">
    <inertial>
      <origin rpy="0 0 0" xyz="0.106 -0.106 0"/>
      <mass value="0"/>
      <inertia ixx="0" ixy="0" ixz="0" iyy="0" iyz="0" izz="0"/>
    </inertial>
    <visual>
      <origin rpy="0 0 0" xyz="0.106 -0.106 0.02"/>
      <geometry>
          <mesh filename="./mesh/a300/prop.dae"  scale="0.4 0.4 0.4"/>
      </geometry> 
    </visual>
  </link>
  <joint name="prop0_joint" type="fixed">
    <parent link="base_link"/>
    <child link="prop0_link"/>
  </joint>

  <link name="prop1_link">
    <inertial>
      <origin rpy="0 0 0" xyz="-0.106 0.106 0"/>
      <mass value="0"/>
      <inertia ixx="0" ixy="0" ixz="0" iyy="0" iyz="0" izz="0"/>
    </inertial>
    <visual>
      <origin rpy="0 0 0" xyz="-0.106 0.106 0.02"/>
      <geometry>
          <mesh filename="./mesh/a300/prop.dae"  scale="0.4 0.4 0.4"/>
      </geometry> 
    </visual>
  </link>
  <joint name="prop1_joint" type="fixed">
    <parent link="base_link"/>
    <child link="prop1_link"/>
  </joint>

  <link name="prop2_link">
    <inertial>
      <origin rpy="0 0 0" xyz="0.106 0.106 0"/>
      <mass value="0"/>
      <inertia ixx="0" ixy="0" ixz="0" iyy="0" iyz="0" izz="0"/>
    </inertial>
    <visual>
      <origin rpy="0 0 0" xyz="0.106 0.106 0.02"/>
      <geometry>
          <mesh filename="./mesh/a300/prop.dae"  scale="0.4 0.4 0.4"/>
      </geometry>
    </visual>
  </link>
  <joint name="prop2_joint" type="fixed">
    <parent link="base_link"/>
    <child link="prop2_link"/>
  </joint>

  <link name="prop3_link">
    <inertial>
      <origin rpy="0 0 0" xyz="-0.106 -0.106 0"/>
      <mass value="0"/>
      <inertia ixx="0" ixy="0" ixz="0" iyy="0" iyz="0" izz="0"/>
    </inertial>
    <visual>
      <origin rpy="0 0 0" xyz="-0.106 -0.106 0.02"/>
      <geometry>
          <mesh filename="./mesh/a300/prop.dae"  scale="0.4 0.4 0.4"/>
      </geometry>
    </visual>
  </link>
  <joint name="prop3_joint" type="fixed">
    <parent link="base_link"/>
    <child link="prop3_link"/>
  </joint>

  <link name="center_of_mass_link">
    <inertial>
      <origin rpy="0 0 0" xyz="0 0 0"/>
      <mass value="0"/>
      <inertia ixx="0" ixy="0" ixz="0" iyy="0" iyz="0" izz="0"/>
    </inertial>
  </link>
  <joint name="center_of_mass_joint" type="fixed">
    <parent link="base_link"/>
    <child link="center_of_mass_link"/>
  </joint>



<!-- Rope -->
  <!-- Spherical joint -->
  <link name="segment_1_sphere">
    <visual>
      <geometry>
        <sphere radius="0.005"/>
      </geometry>
      <material name="gray"/>
    </visual>
    <collision>
      <geometry>
        <sphere radius="0.005"/>
      </geometry>
    </collision>
    <inertial>
      <mass value="1e-04"/>
      <inertia ixx="1e-6" ixy="0" ixz="0" iyy="1e-6" iyz="0" izz="1e-6"/>
    </inertial>
  </link>
  <joint name="center_of_mass_link_to_segment_1_sphere" type="revolute">
    <parent link="center_of_mass_link"/>
    <child link="segment_1_sphere"/>
    <origin rpy="0 0 0" xyz="0 0 -0.015"/>
    <axis xyz="0 1 0"/>
    <limit effort="10" lower="-3.14" upper="3.14" velocity="3"/>
    <dynamics damping="0.1" friction="0.0"/>
  </joint>
  <!-- Cylinder segment -->
  <link name="segment_1_cylinder">
    <visual>
      <geometry>
        <cylinder length="0.01" radius="0.005"/>
      </geometry>
      <origin rpy="0 0 0" xyz="0 0 -0.0075"/>
      <material name="blue"/>
    </visual>
<!--  <collision>
      <geometry>
        <cylinder length="0.01" radius="0.005"/>
      </geometry>
      <origin rpy="0 0 0" xyz="0 0 -0.0075"/>
    </collision> -->
    <inertial>
      <mass value="0.0001"/>
      <inertia ixx="2.5e-05" ixy="0" ixz="0" iyy="2.5e-05" iyz="0" izz="1.25e-05"/>
      <origin rpy="0 0 0" xyz="0 0 -0.0075"/>
    </inertial>
  </link>
  <joint name="segment_1_sphere_to_cylinder" type="revolute">
    <parent link="segment_1_sphere"/>
    <child link="segment_1_cylinder"/>
    <origin rpy="0 0 0" xyz="0 0 0"/>
    <axis xyz="1 0 0"/>
    <limit effort="10" lower="-3.14" upper="3.14" velocity="3"/>
    <dynamics damping="0.1" friction="0.0"/>
  </joint>

  <!-- Spherical joint -->
  <link name="segment_2_sphere">
    <visual>
      <geometry>
        <sphere radius="0.005"/>
      </geometry>
      <material name="gray"/>
    </visual>
    <collision>
      <geometry>
        <sphere radius="0.005"/>
      </geometry>
    </collision>
    <inertial>
      <mass value="1e-04"/> # -6
      <inertia ixx="1e-6" ixy="0" ixz="0" iyy="1e-6" iyz="0" izz="1e-6"/> # -12
    </inertial>
  </link>
  <joint name="segment_1_cylinder_to_segment_2_sphere" type="revolute">
    <parent link="segment_1_cylinder"/>
    <child link="segment_2_sphere"/>
    <origin rpy="0 0 0" xyz="0 0 -0.015"/>
    <axis xyz="0 1 0"/>
    <limit effort="10" lower="-3.14" upper="3.14" velocity="3"/>
    <dynamics damping="0.1" friction="0.0"/>
  </joint>
  <!-- Cylinder segment -->
  <link name="segment_2_cylinder">
    <visual>
      <geometry>
        <cylinder length="0.01" radius="0.005"/>
      </geometry>
      <origin rpy="0 0 0" xyz="0 0 -0.0075"/>
      <material name="blue"/>
    </visual>
<!--  <collision>
      <geometry>
        <cylinder length="0.01" radius="0.005"/>
      </geometry>
      <origin rpy="0 0 0" xyz="0 0 -0.0075"/>
    </collision> -->
    <inertial>
      <mass value="0.0001"/>
      <inertia ixx="2.5e-05" ixy="0" ixz="0" iyy="2.5e-05" iyz="0" izz="1.25e-05"/> #-9
      <origin rpy="0 0 0" xyz="0 0 -0.0075"/>
    </inertial>
  </link>
  <joint name="segment_2_sphere_to_cylinder" type="revolute">
    <parent link="segment_2_sphere"/>
    <child link="segment_2_cylinder"/>
    <origin rpy="0 0 0" xyz="0 0 0"/>
    <axis xyz="1 0 0"/>
    <limit effort="10" lower="-3.14" upper="3.14" velocity="3"/>
    <dynamics damping="0.1" friction="0.0"/>
  </joint>

  <!-- Spherical joint -->
  <link name="segment_3_sphere">
    <visual>
      <geometry>
        <sphere radius="0.005"/>
      </geometry>
      <material name="gray"/>
    </visual>
    <collision>
      <geometry>
        <sphere radius="0.005"/>
      </geometry>
    </collision>
    <inertial>
      <mass value="1e-04"/>
      <inertia ixx="1e-6" ixy="0" ixz="0" iyy="1e-6" iyz="0" izz="1e-6"/>
    </inertial>
  </link>
  <joint name="segment_2_cylinder_to_segment_3_sphere" type="revolute">
    <parent link="segment_2_cylinder"/>
    <child link="segment_3_sphere"/>
    <origin rpy="0 0 0" xyz="0 0 -0.015"/>
    <axis xyz="0 1 0"/>
    <limit effort="10" lower="-3.14" upper="3.14" velocity="3"/>
    <dynamics damping="0.1" friction="0.0"/>
  </joint>
  <!-- Cylinder segment -->
  <link name="segment_3_cylinder">
    <visual>
      <geometry>
        <cylinder length="0.01" radius="0.005"/>
      </geometry>
      <origin rpy="0 0 0" xyz="0 0 -0.0075"/>
      <material name="blue"/>
    </visual>
<!--  <collision>
      <geometry>
        <cylinder length="0.01" radius="0.005"/>
      </geometry>
      <origin rpy="0 0 0" xyz="0 0 -0.0075"/>
    </collision> -->
    <inertial>
      <mass value="0.0001"/>
      <inertia ixx="2.5e-05" ixy="0" ixz="0" iyy="2.5e-05" iyz="0" izz="1.25e-05"/>
      <origin rpy="0 0 0" xyz="0 0 -0.0075"/>
    </inertial>
  </link>
  <joint name="segment_3_sphere_to_cylinder" type="revolute">
    <parent link="segment_3_sphere"/>
    <child link="segment_3_cylinder"/>
    <origin rpy="0 0 0" xyz="0 0 0"/>
    <axis xyz="1 0 0"/>
    <limit effort="10" lower="-3.14" upper="3.14" velocity="3"/>
    <dynamics damping="0.1" friction="0.0"/>
  </joint>

  <!-- Spherical joint -->
  <link name="segment_4_sphere">
    <visual>
      <geometry>
        <sphere radius="0.005"/>
      </geometry>
      <material name="gray"/>
    </visual>
    <collision>
      <geometry>
        <sphere radius="0.005"/>
      </geometry>
    </collision>
    <inertial>
      <mass value="1e-04"/>
      <inertia ixx="1e-6" ixy="0" ixz="0" iyy="1e-6" iyz="0" izz="1e-6"/>
    </inertial>
  </link>
  <joint name="segment_3_cylinder_to_segment_4_sphere" type="revolute">
    <parent link="segment_3_cylinder"/>
    <child link="segment_4_sphere"/>
    <origin rpy="0 0 0" xyz="0 0 -0.015"/>
    <axis xyz="0 1 0"/>
    <limit effort="10" lower="-3.14" upper="3.14" velocity="3"/>
    <dynamics damping="0.1" friction="0.0"/>
  </joint>
  <!-- Cylinder segment -->
  <link name="segment_4_cylinder">
    <visual>
      <geometry>
        <cylinder length="0.01" radius="0.005"/>
      </geometry>
      <origin rpy="0 0 0" xyz="0 0 -0.0075"/>
      <material name="blue"/>
    </visual>
<!--  <collision>
      <geometry>
        <cylinder length="0.01" radius="0.005"/>
      </geometry>
      <origin rpy="0 0 0" xyz="0 0 -0.0075"/>
    </collision> -->
    <inertial>
      <mass value="0.0001"/>
      <inertia ixx="2.5e-05" ixy="0" ixz="0" iyy="2.5e-05" iyz="0" izz="1.25e-05"/>
      <origin rpy="0 0 0" xyz="0 0 -0.0075"/>
    </inertial>
  </link>
  <joint name="segment_4_sphere_to_cylinder" type="revolute">
    <parent link="segment_4_sphere"/>
    <child link="segment_4_cylinder"/>
    <origin rpy="0 0 0" xyz="0 0 0"/>
    <axis xyz="1 0 0"/>
    <limit effort="10" lower="-3.14" upper="3.14" velocity="3"/>
    <dynamics damping="0.1" friction="0.0"/>
  </joint>

  <!-- Spherical joint -->
  <link name="segment_5_sphere">
    <visual>
      <geometry>
        <sphere radius="0.005"/>
      </geometry>
      <material name="gray"/>
    </visual>
    <collision>
      <geometry>
        <sphere radius="0.005"/>
      </geometry>
    </collision>
    <inertial>
      <mass value="1e-04"/>
      <inertia ixx="1e-6" ixy="0" ixz="0" iyy="1e-6" iyz="0" izz="1e-6"/>
    </inertial>
  </link>
  <joint name="segment_4_cylinder_to_segment_5_sphere" type="revolute">
    <parent link="segment_4_cylinder"/>
    <child link="segment_5_sphere"/>
    <origin rpy="0 0 0" xyz="0 0 -0.015"/>
    <axis xyz="0 1 0"/>
    <limit effort="10" lower="-3.14" upper="3.14" velocity="3"/>
    <dynamics damping="0.1" friction="0.0"/>
  </joint>
  <!-- Cylinder segment -->
  <link name="segment_5_cylinder">
    <visual>
      <geometry>
        <cylinder length="0.01" radius="0.005"/>
      </geometry>
      <origin rpy="0 0 0" xyz="0 0 -0.0075"/>
      <material name="blue"/>
    </visual>
<!--  <collision>
      <geometry>
        <cylinder length="0.01" radius="0.005"/>
      </geometry>
      <origin rpy="0 0 0" xyz="0 0 -0.0075"/>
    </collision> -->
    <inertial>
      <mass value="0.0001"/>
      <inertia ixx="2.5e-05" ixy="0" ixz="0" iyy="2.5e-05" iyz="0" izz="1.25e-05"/>
      <origin rpy="0 0 0" xyz="0 0 -0.0075"/>
    </inertial>
  </link>
  <joint name="segment_5_sphere_to_cylinder" type="revolute">
    <parent link="segment_5_sphere"/>
    <child link="segment_5_cylinder"/>
    <origin rpy="0 0 0" xyz="0 0 0"/>
    <axis xyz="1 0 0"/>
    <limit effort="10" lower="-3.14" upper="3.14" velocity="3"/>
    <dynamics damping="0.1" friction="0.0"/>
  </joint>

  <!-- Spherical joint -->
  <link name="segment_6_sphere">
    <visual>
      <geometry>
        <sphere radius="0.005"/>
      </geometry>
      <material name="gray"/>
    </visual>
    <collision>
      <geometry>
        <sphere radius="0.005"/>
      </geometry>
    </collision>
    <inertial>
      <mass value="1e-04"/>
      <inertia ixx="1e-6" ixy="0" ixz="0" iyy="1e-6" iyz="0" izz="1e-6"/>
    </inertial>
  </link>
  <joint name="segment_5_cylinder_to_segment_6_sphere" type="revolute">
    <parent link="segment_5_cylinder"/>
    <child link="segment_6_sphere"/>
    <origin rpy="0 0 0" xyz="0 0 -0.015"/>
    <axis xyz="0 1 0"/>
    <limit effort="10" lower="-3.14" upper="3.14" velocity="3"/>
    <dynamics damping="0.1" friction="0.0"/>
  </joint>
  <!-- Cylinder segment -->
  <link name="segment_6_cylinder">
    <visual>
      <geometry>
        <cylinder length="0.01" radius="0.005"/>
      </geometry>
      <origin rpy="0 0 0" xyz="0 0 -0.0075"/>
      <material name="blue"/>
    </visual>
<!--  <collision>
      <geometry>
        <cylinder length="0.01" radius="0.005"/>
      </geometry>
      <origin rpy="0 0 0" xyz="0 0 -0.0075"/>
    </collision> -->
    <inertial>
      <mass value="0.0001"/>
      <inertia ixx="2.5e-05" ixy="0" ixz="0" iyy="2.5e-05" iyz="0" izz="1.25e-05"/>
      <origin rpy="0 0 0" xyz="0 0 -0.0075"/>
    </inertial>
  </link>
  <joint name="segment_6_sphere_to_cylinder" type="revolute">
    <parent link="segment_6_sphere"/>
    <child link="segment_6_cylinder"/>
    <origin rpy="0 0 0" xyz="0 0 0"/>
    <axis xyz="1 0 0"/>
    <limit effort="10" lower="-3.14" upper="3.14" velocity="3"/>
    <dynamics damping="0.1" friction="0.0"/>
  </joint>

  <!-- Spherical joint -->
  <link name="segment_7_sphere">
    <visual>
      <geometry>
        <sphere radius="0.005"/>
      </geometry>
      <material name="gray"/>
    </visual>
    <collision>
      <geometry>
        <sphere radius="0.005"/>
      </geometry>
    </collision>
    <inertial>
      <mass value="1e-04"/>
      <inertia ixx="1e-6" ixy="0" ixz="0" iyy="1e-6" iyz="0" izz="1e-6"/>
    </inertial>
  </link>
  <joint name="segment_6_cylinder_to_segment_7_sphere" type="revolute">
    <parent link="segment_6_cylinder"/>
    <child link="segment_7_sphere"/>
    <origin rpy="0 0 0" xyz="0 0 -0.015"/>
    <axis xyz="0 1 0"/>
    <limit effort="10" lower="-3.14" upper="3.14" velocity="3"/>
    <dynamics damping="0.1" friction="0.0"/>
  </joint>
  <!-- Cylinder segment -->
  <link name="segment_7_cylinder">
    <visual>
      <geometry>
        <cylinder length="0.01" radius="0.005"/>
      </geometry>
      <origin rpy="0 0 0" xyz="0 0 -0.0075"/>
      <material name="blue"/>
    </visual>
<!--  <collision>
      <geometry>
        <cylinder length="0.01" radius="0.005"/>
      </geometry>
      <origin rpy="0 0 0" xyz="0 0 -0.0075"/>
    </collision> -->
    <inertial>
      <mass value="0.0001"/>
      <inertia ixx="2.5e-05" ixy="0" ixz="0" iyy="2.5e-05" iyz="0" izz="1.25e-05"/>
      <origin rpy="0 0 0" xyz="0 0 -0.0075"/>
    </inertial>
  </link>
  <joint name="segment_7_sphere_to_cylinder" type="revolute">
    <parent link="segment_7_sphere"/>
    <child link="segment_7_cylinder"/>
    <origin rpy="0 0 0" xyz="0 0 0"/>
    <axis xyz="1 0 0"/>
    <limit effort="10" lower="-3.14" upper="3.14" velocity="3"/>
    <dynamics damping="0.1" friction="0.0"/>
  </joint>

  <!-- Spherical joint -->
  <link name="segment_8_sphere">
    <visual>
      <geometry>
        <sphere radius="0.005"/>
      </geometry>
      <material name="gray"/>
    </visual>
    <collision>
      <geometry>
        <sphere radius="0.005"/>
      </geometry>
    </collision>
    <inertial>
      <mass value="1e-04"/>
      <inertia ixx="1e-6" ixy="0" ixz="0" iyy="1e-6" iyz="0" izz="1e-6"/>
    </inertial>
  </link>
  <joint name="segment_7_cylinder_to_segment_8_sphere" type="revolute">
    <parent link="segment_7_cylinder"/>
    <child link="segment_8_sphere"/>
    <origin rpy="0 0 0" xyz="0 0 -0.015"/>
    <axis xyz="0 1 0"/>
    <limit effort="10" lower="-3.14" upper="3.14" velocity="3"/>
    <dynamics damping="0.1" friction="0.0"/>
  </joint>
  <!-- Cylinder segment -->
  <link name="segment_8_cylinder">
    <visual>
      <geometry>
        <cylinder length="0.01" radius="0.005"/>
      </geometry>
      <origin rpy="0 0 0" xyz="0 0 -0.0075"/>
      <material name="blue"/>
    </visual>
<!--  <collision>
      <geometry>
        <cylinder length="0.01" radius="0.005"/>
      </geometry>
      <origin rpy="0 0 0" xyz="0 0 -0.0075"/>
    </collision> -->
    <inertial>
      <mass value="0.0001"/>
      <inertia ixx="2.5e-05" ixy="0" ixz="0" iyy="2.5e-05" iyz="0" izz="1.25e-05"/>
      <origin rpy="0 0 0" xyz="0 0 -0.0075"/>
    </inertial>
  </link>
  <joint name="segment_8_sphere_to_cylinder" type="revolute">
    <parent link="segment_8_sphere"/>
    <child link="segment_8_cylinder"/>
    <origin rpy="0 0 0" xyz="0 0 0"/>
    <axis xyz="1 0 0"/>
    <limit effort="10" lower="-3.14" upper="3.14" velocity="3"/>
    <dynamics damping="0.1" friction="0.0"/>
  </joint>

  <!-- Spherical joint -->
  <link name="segment_9_sphere">
    <visual>
      <geometry>
        <sphere radius="0.005"/>
      </geometry>
      <material name="gray"/>
    </visual>
    <collision>
      <geometry>
        <sphere radius="0.005"/>
      </geometry>
    </collision>
    <inertial>
      <mass value="1e-04"/>
      <inertia ixx="1e-6" ixy="0" ixz="0" iyy="1e-6" iyz="0" izz="1e-6"/>
    </inertial>
  </link>
  <joint name="segment_8_cylinder_to_segment_9_sphere" type="revolute">
    <parent link="segment_8_cylinder"/>
    <child link="segment_9_sphere"/>
    <origin rpy="0 0 0" xyz="0 0 -0.015"/>
    <axis xyz="0 1 0"/>
    <limit effort="10" lower="-3.14" upper="3.14" velocity="3"/>
    <dynamics damping="0.1" friction="0.0"/>
  </joint>
  <!-- Cylinder segment -->
  <link name="segment_9_cylinder">
    <visual>
      <geometry>
        <cylinder length="0.01" radius="0.005"/>
      </geometry>
      <origin rpy="0 0 0" xyz="0 0 -0.0075"/>
      <material name="blue"/>
    </visual>
<!--  <collision>
      <geometry>
        <cylinder length="0.01" radius="0.005"/>
      </geometry>
      <origin rpy="0 0 0" xyz="0 0 -0.0075"/>
    </collision> -->
    <inertial>
      <mass value="0.0001"/>
      <inertia ixx="2.5e-05" ixy="0" ixz="0" iyy="2.5e-05" iyz="0" izz="1.25e-05"/>
      <origin rpy="0 0 0" xyz="0 0 -0.0075"/>
    </inertial>
  </link>
  <joint name="segment_9_sphere_to_cylinder" type="revolute">
    <parent link="segment_9_sphere"/>
    <child link="segment_9_cylinder"/>
    <origin rpy="0 0 0" xyz="0 0 0"/>
    <axis xyz="1 0 0"/>
    <limit effort="10" lower="-3.14" upper="3.14" velocity="3"/>
    <dynamics damping="0.1" friction="0.0"/>
  </joint>

  <!-- Spherical joint -->
  <link name="segment_10_sphere">
    <visual>
      <geometry>
        <sphere radius="0.005"/>
      </geometry>
      <material name="gray"/>
    </visual>
    <collision>
      <geometry>
        <sphere radius="0.005"/>
      </geometry>
    </collision>
    <inertial>
      <mass value="1e-04"/>
      <inertia ixx="1e-6" ixy="0" ixz="0" iyy="1e-6" iyz="0" izz="1e-6"/>
    </inertial>
  </link>
  <joint name="segment_9_cylinder_to_segment_10_sphere" type="revolute">
    <parent link="segment_9_cylinder"/>
    <child link="segment_10_sphere"/>
    <origin rpy="0 0 0" xyz="0 0 -0.015"/>
    <axis xyz="0 1 0"/>
    <limit effort="10" lower="-3.14" upper="3.14" velocity="3"/>
    <dynamics damping="0.1" friction="0.0"/>
  </joint>
  <!-- Cylinder segment -->
  <link name="segment_10_cylinder">
    <visual>
      <geometry>
        <cylinder length="0.01" radius="0.005"/>
      </geometry>
      <origin rpy="0 0 0" xyz="0 0 -0.0075"/>
      <material name="blue"/>
    </visual>
<!--  <collision>
      <geometry>
        <cylinder length="0.01" radius="0.005"/>
      </geometry>
      <origin rpy="0 0 0" xyz="0 0 -0.0075"/>
    </collision> -->
    <inertial>
      <mass value="0.0001"/>
      <inertia ixx="2.5e-05" ixy="0" ixz="0" iyy="2.5e-05" iyz="0" izz="1.25e-05"/>
      <origin rpy="0 0 0" xyz="0 0 -0.0075"/>
    </inertial>
  </link>
  <joint name="segment_10_sphere_to_cylinder" type="revolute">
    <parent link="segment_10_sphere"/>
    <child link="segment_10_cylinder"/>
    <origin rpy="0 0 0" xyz="0 0 0"/>
    <axis xyz="1 0 0"/>
    <limit effort="10" lower="-3.14" upper="3.14" velocity="3"/>
    <dynamics damping="0.1" friction="0.0"/>
  </joint>

  <!-- <link name="end_cylinder">
    <visual>
      <origin rpy="1.5708 1.5708 0" xyz="0.0 0.5 0"/>
      <geometry>
        <cylinder length="1.0" radius="0.01"/>
      </geometry>
      <material name="pink"/>
    </visual>
    <collision>
      <origin rpy="0 1.5708 0" xyz="0 0 0"/>
      <geometry>
        <cylinder length="0.2" radius="0.01"/>
      </geometry>
    </collision>
    <inertial>
      <mass value="0.068"/>
      <inertia ixx="0.000227" ixy="0" ixz="0" iyy="0.000227" iyz="0" izz="0.0000034"/>
    </inertial>
  </link>

  <joint name="joint_end_cylinder" type="revolute">
    <parent link="segment_10_cylinder"/>
    <child link="end_cylinder"/>
    <origin rpy="0 0 0" xyz="0 0 -0.015"/>
    <axis xyz="0 1 0"/>
    <limit effort="10" lower="-3.14" upper="3.14" velocity="3"/>
    <dynamics damping="0.1" friction="0.0"/>
  </joint> -->

</robot>
